Workbook

Sheet Hoja1
A4: 05/10/2026 0:00 | B4: BO_FS_202605101685516_29162712 | C4: 29162712 | D4: NULL | E4: 05/10/2026 0:002 | F4: NULL3 | G4: NULL4 | H4: Mario cesar GONZALES ORTIZ | I4: 1685516 | J4: NULL5 | K4: ce_ortiz@yahoo.es | L4: Reparacion | M4: 05/10/2026 0:006 | N4: Soporte tecnico | O4: No | P4: NULL7 | Q4: 10 | R4: Atentos loa señores buen swrvicio | S4: NULL8 | T4: NULL9 | U4: NULL10 | V4: SI | W4: Yes | X4: HFC | Y4: NULL11 | Z4: PROMOTOR | AA4: NULL12 | AB4: NULL13 | AC4: NULL14 | AD4: NULL15 | AE4: NULL16 | AF4: NULL17 | AG4: NULL18 | AH4: SANTA CRUZ | AI4: SANTA CRUZ | AJ4: JOSE JONATHAN VERA GUTIERREZ | AK4: 168551619 | AL4: 2916271220 | AM4: Mario cesar GONZALES ORTIZ21 | AN4: CONECTADO | AO4: SANTA CRUZ 22 | AP4: EAST | AQ4: SANTA CRUZ 23 | AR4: URBANA | AS4: HFC24 | AT4: R | AU4: FINALIZADA | AV4: 05/08/2026 0:00 | AW4: 05/08/2026 20:13 | AX4: 202605 | AY4: 1025 | AZ4: 05/10/2026 0:0026 | BA4: 05/10/2026 12:33 | BB4: NODO SCZ284 | BC4: NODO SCZ284 RAMAL B TAP 026 | BD4: MAKIRO | BE4: 3744 | BF4: DANIEL CARREÑO ROJAS | BG4: MAKIRO27 | BH4: 06/01/2026 16:02 | BI4: 18298 | BJ4: Columna1 | BK4: =VLOOKUP(Hoja1!$B4,Hoja2!B2:B34,1,FALSE) -> #N/A
A5: 46300 | B5: BO_FS_202605102524934_29160908 | C5: 29160908 | D5: NULL | E5: 46300 | F5: NULL | G5: NULL | H5: luis pablo AVALOS TOLEDO | I5: 2524934 | J5: NULL | K5: pabloavalos200215@gmail.com | L5: Reparacion | M5: 46300 | N5: Soporte tecnico | O5: No | P5: NULL | Q5: 10 | R5: NULL | S5: NULL | T5: NULL | U5: NULL | V5: SI | W5: Yes | X5: HFC | Y5: NULL | Z5: PROMOTOR | AA5: NULL | AB5: NULL | AC5: NULL | AD5: NULL | AE5: NULL | AF5: NULL | AG5: NULL | AH5: SANTA CRUZ | AI5: SANTA CRUZ CAP | AJ5: JOSE JONATHAN VERA GUTIERREZ | AK5: 2524934 | AL5: 29160908 | AM5: luis pablo AVALOS TOLEDO | AN5: CONECTADO | AO5: SANTA CRUZ | AP5: EAST | AQ5: SANTA CRUZ CAP | AR5: URBANA | AS5: HFC | AT5: R | AU5: FINALIZADA | AV5: 46239 | AW5: 46239.606 | AX5: 202605 | AY5: 10 | AZ5: 46300 | BA5: 46300.43 | BB5: NODO SCZ266 | BC5: NODO SCZ266 RAMAL B TAP 011 | BD5: MAKIRO | BE5: 3744 | BF5: DANIEL CARREÑO ROJAS | BG5: MAKIRO | BH5: 25/05/2026 16:02:39 | BI5: 16182 | BJ5: =CONS -> #NAME? | BK5: =VLOOKUP(Hoja1!$B5,Tabla2[[#All],[ID_TRANSACCION]],1,FALSE) -> #N/A
A6: 46239 | B6: BO_FS_202605082659753_29158085 | C6: 29158085 | D6: NULL | E6: 46300 | F6: NULL | G6: NULL | H6: CRISTIAN CHUVE CHUVIRU | I6: 2659753 | J6: NULL | K6: cristian.chuvechu@gmail.com | L6: Instalacion | M6: 46239 | N6: Instalacion / Activacion | O6: No | P6: NULL | Q6: 10 | R6: Excelente trabajo | S6: NULL | T6: NULL | U6: NULL | V6: SI | W6: Yes | X6: HFC | Y6: NULL | Z6: PROMOTOR | AA6: NULL | AB6: NULL | AC6: NULL | AD6: NULL | AE6: NULL | AF6: NULL | AG6: NULL | AH6: SANTA CRUZ | AI6: SANTA CRUZ CAP | AJ6: JOSE JONATHAN VERA GUTIERREZ | AK6: 2659753 | AL6: 29158085 | AM6: CRISTIAN CHUVE CHUVIRU | AN6: CONECTADO | AO6: SANTA CRUZ | AP6: EAST | AQ6: SANTA CRUZ CAP | AR6: URBANA | AS6: HFC | AT6: I | AU6: FINALIZADA | AV6: 46208 | AW6: 46208.808 | AX6: 202605 | AY6: 8 | AZ6: 46239 | BA6: 46239.641 | BB6: NODO SCZ270 | BC6: NODO SCZ270 RAMAL B TAP 025 | BD6: MAKIRO | BE6: 3744 | BF6: DANIEL CARREÑO ROJAS | BG6: MAKIRO | BH6: 25/05/2026 16:02:39 | BI6: 16200 | BJ6: =CONS -> #NAME? | BK6: =VLOOKUP(Hoja1!$B6,Tabla2[[#All],[ID_TRANSACCION]],1,FALSE) -> BO_FS_202605082659753_29158085
A7: 46208 | B7: BO_FS_202605072658950_29152051 | C7: 29152051 | D7: NULL | E7: 46239 | F7: NULL | G7: NULL | H7: Katalina LOPEZ EGUEZ | I7: 2658950 | J7: NULL | K7: Lopezeguezkatalina@gmail.com | L7: Instalacion | M7: 46208 | N7: Instalacion / Activacion | O7: No | P7: NULL | Q7: 10 | R7: Muy bien servicio | S7: NULL | T7: NULL | U7: NULL | V7: SI | W7: Yes | X7: HFC | Y7: NULL | Z7: PROMOTOR | AA7: NULL | AB7: NULL | AC7: NULL | AD7: NULL | AE7: NULL | AF7: NULL | AG7: NULL | AH7: SANTA CRUZ | AI7: SANTA CRUZ CAP | AJ7: JOSE JONATHAN VERA GUTIERREZ | AK7: 2658950 | AL7: 29152051 | AM7: Katalina LÓPEZ EGUEZ | AN7: CONECTADO | AO7: SANTA CRUZ | AP7: EAST | AQ7: SANTA CRUZ CAP | AR7: URBANA | AS7: HFC | AT7: I | AU7: FINALIZADA | AV7: 46178 | AW7: 46178.661 | AX7: 202605 | AY7: 7 | AZ7: 46208 | BA7: 46208.638 | BB7: NODO SCZ321 | BC7: NODO SCZ321 RAMAL D TAP 007 | BD7: MAKIRO | BE7: 3744 | BF7: DANIEL CARREÑO ROJAS | BG7: MAKIRO | BH7: 25/05/2026 16:02:39 | BI7: 16224 | BJ7: =CONS -> #NAME? | BK7: =VLOOKUP(Hoja1!$B7,Tabla2[[#All],[ID_TRANSACCION]],1,FALSE) -> BO_FS_202605072658950_29152051
A8: 30/04/2026 0:00:00 | B8: BO_FS_202604302654827_29100462 | C8: 29100462 | D8: NULL | E8: 30/04/2026 0:00:00 | F8: NULL | G8: NULL | H8: Onesimo RIVERA ORTEGA | I8: 2654827 | J8: NULL | K8: onesimojd12@gmail.com | L8: Instalacion | M8: 30/04/2026 0:00:00 | N8: Instalacion / Activacion | O8: No | P8: NULL | Q8: 10 | R8: Gracias | S8: NULL | T8: NULL | U8: NULL | V8: SI | W8: Yes | X8: HFC | Y8: NULL | Z8: PROMOTOR | AA8: NULL | AB8: NULL | AC8: NULL | AD8: NULL | AE8: NULL | AF8: NULL | AG8: NULL | AH8: SANTA CRUZ | AI8: SANTA CRUZ CAP | AJ8: JOSE JONATHAN VERA GUTIERREZ | AK8: 2654827 | AL8: 29100462 | AM8: Onesimo RIVERA ORTEGA | AN8: CONECTADO | AO8: SANTA CRUZ | AP8: EAST | AQ8: SANTA CRUZ CAP | AR8: URBANA | AS8: HFC | AT8: I | AU8: FINALIZADA | AV8: 28/04/2026 0:00:00 | AW8: 28/04/2026 22:21:56 | AX8: 202604 | AY8: 30 | AZ8: 30/04/2026 0:00:00 | BA8: 30/04/2026 10:37:39 | BB8: NODO SCZ285 | BC8: NODO SCZ285 RAMAL C TAP 052 | BD8: MAKIRO | BE8: 3744 | BF8: DANIEL CARREÑO ROJAS | BG8: MAKIRO | BH8: 25/05/2026 16:02:39 | BI8: 16277 | BJ8: =CONS -> #NAME? | BK8: =VLOOKUP(Hoja1!$B8,Tabla2[[#All],[ID_TRANSACCION]],1,FALSE) -> #N/A
A9: 29/04/2026 0:00:00 | B9: BO_FS_202604292654801_29100312 | C9: 29100312 | D9: NULL | E9: 30/04/2026 0:00:00 | F9: NULL | G9: NULL | H9: HERNAN CORTEZ PEREZ | I9: 2654801 | J9: NULL | K9: Hernancortez71@gmail.com | L9: Instalacion | M9: 29/04/2026 0:00:00 | N9: Instalacion / Activacion | O9: No | P9: NULL | Q9: 9 | R9: Buena atención amables cumplían consu equipo de trabajo su uniformes que lo identifica | S9: NULL | T9: NULL | U9: NULL | V9: SI | W9: Yes | X9: HFC | Y9: NULL | Z9: PROMOTOR | AA9: NULL | AB9: NULL | AC9: NULL | AD9: NULL | AE9: NULL | AF9: NULL | AG9: NULL | AH9: SANTA CRUZ | AI9: SANTA CRUZ CAP | AJ9: JOSE JONATHAN VERA GUTIERREZ | AK9: 2654801 | AL9: 29100312 | AM9: HERNAN CORTEZ PEREZ | AN9: CONECTADO | AO9: SANTA CRUZ | AP9: EAST | AQ9: SANTA CRUZ CAP | AR9: URBANA | AS9: HFC | AT9: I | AU9: FINALIZADA | AV9: 28/04/2026 0:00:00 | AW9: 28/04/2026 20:47:20 | AX9: 202604 | AY9: 29 | AZ9: 29/04/2026 0:00:00 | BA9: 29/04/2026 17:51:27 | BB9: NODO SCZ318 | BC9: NODO SCZ318 RAMAL A TAP 052 | BD9: MAKIRO | BE9: 3744 | BF9: DANIEL CARREÑO ROJAS | BG9: MAKIRO | BH9: 25/05/2026 16:02:39 | BI9: 16278 | BJ9: =CONS -> #NAME? | BK9: =VLOOKUP(Hoja1!$B9,Tabla2[[#All],[ID_TRANSACCION]],1,FALSE) -> #N/A
A10: 29/04/2026 0:00:00 | B10: BO_FS_202604292655091_29103341 | C10: 29103341 | D10: NULL | E10: 30/04/2026 0:00:00 | F10: NULL | G10: NULL | H10: Leslie Katherine CHOQUE BLANCO | I10: 2655091 | J10: NULL | K10: Leslie@gmail.com | L10: Instalacion | M10: 29/04/2026 0:00:00 | N10: Instalacion / Activacion | O10: No | P10: NULL | Q10: 10 | R10: La instalación fué rápida, no tardó ni 30 minutos. Es muy recomendable | S10: NULL | T10: NULL | U10: NULL | V10: SI | W10: Yes | X10: HFC | Y10: NULL | Z10: PROMOTOR | AA10: NULL | AB10: NULL | AC10: NULL | AD10: NULL | AE10: NULL | AF10: NULL | AG10: NULL | AH10: SANTA CRUZ | AI10: SANTA CRUZ CAP | AJ10: JOSE JONATHAN VERA GUTIERREZ | AK10: 2655091 | AL10: 29103341 | AM10: Leslie Katherine CHOQUE BLANCO | AN10: CONECTADO | AO10: SANTA CRUZ | AP10: EAST | AQ10: SANTA CRUZ CAP | AR10: URBANA | AS10: HFC | AT10: I | AU10: FINALIZADA | AV10: 29/04/2026 0:00:00 | AW10: 29/04/2026 13:10:42 | AX10: 202604 | AY10: 29 | AZ10: 29/04/2026 0:00:00 | BA10: 29/04/2026 15:28:14 | BB10: NODO SCZ414 | BC10: NODO SCZ414 RAMAL D TAP 013 | BD10: MAKIRO | BE10: 3744 | BF10: DANIEL CARREÑO ROJAS | BG10: MAKIRO | BH10: 25/05/2026 16:02:39 | BI10: 16279 | BJ10: =CONS -> #NAME? | BK10: =VLOOKUP(Hoja1!$B10,Tabla2[[#All],[ID_TRANSACCION]],1,FALSE) -> #N/A
A11: 24/04/2026 0:00:00 | B11: BO_FS_202604242652458_28970298 | C11: 28970298 | D11: NULL | E11: 24/04/2026 0:00:00 | F11: NULL | G11: NULL | H11: IVAN ROLANDO JACUMANI MENDOZA | I11: 2652458 | J11: NULL | K11: Not@gmail.com | L11: Instalacion | M11: 24/04/2026 0:00:00 | N11: Instalacion / Activacion | O11: No | P11: NULL | Q11: 9 | R11: Trabajo eficaz | S11: NULL | T11: NULL | U11: NULL | V11: SI | W11: Yes | X11: HFC | Y11: NULL | Z11: PROMOTOR | AA11: NULL | AB11: NULL | AC11: NULL | AD11: NULL | AE11: NULL | AF11: NULL | AG11: NULL | AH11: SANTA CRUZ | AI11: SANTA CRUZ CAP | AJ11: JOSE JONATHAN VERA GUTIERREZ | AK11: 2652458 | AL11: 28970298 | AM11: IVÁN ROLANDO JACUMANI MENDOZA | AN11: CONECTADO | AO11: SANTA CRUZ | AP11: EAST | AQ11: SANTA CRUZ CAP | AR11: URBANA | AS11: HFC | AT11: I | AU11: FINALIZADA | AV11: 23/04/2026 0:00:00 | AW11: 23/04/2026 16:11:34 | AX11: 202604 | AY11: 24 | AZ11: 24/04/2026 0:00:00 | BA11: 24/04/2026 11:09:54 | BB11: NODO SCZ275 | BC11: NODO SCZ275 RAMAL D TAP 062 | BD11: MAKIRO | BE11: 3744 | BF11: DANIEL CARREÑO ROJAS | BG11: MAKIRO | BH11: 25/05/2026 16:02:39 | BI11: 16328 | BJ11: =CONS -> #NAME? | BK11: =VLOOKUP(Hoja1!$B11,Tabla2[[#All],[ID_TRANSACCION]],1,FALSE) -> #N/A
A12: 24/04/2026 0:00:00 | B12: BO_FS_202604242652001_28904211 | C12: 28904211 | D12: NULL | E12: 24/04/2026 0:00:00 | F12: NULL | G12: NULL | H12: Luis Fernando QUIROGA TOLEDO | I12: 2652001 | J12: NULL | K12: Luisfer21@gmail.com | L12: Instalacion | M12: 24/04/2026 0:00:00 | N12: Instalacion / Activacion | O12: No | P12: NULL | Q12: 10 | R12: Por el servicio que brindan | S12: NULL | T12: NULL | U12: NULL | V12: SI | W12: Yes | X12: HFC | Y12: NULL | Z12: PROMOTOR | AA12: NULL | AB12: NULL | AC12: NULL | AD12: NULL | AE12: NULL | AF12: NULL | AG12: NULL | AH12: SANTA CRUZ | AI12: SANTA CRUZ CAP | AJ12: JOSE JONATHAN VERA GUTIERREZ | AK12: 2652001 | AL12: 28904211 | AM12: Luis Fernando QUIROGA TOLEDO | AN12: CONECTADO | AO12: SANTA CRUZ | AP12: EAST | AQ12: SANTA CRUZ CAP | AR12: URBANA | AS12: HFC | AT12: I | AU12: FINALIZADA | AV12: 22/04/2026 0:00:00 | AW12: 22/04/2026 17:36:25 | AX12: 202604 | AY12: 24 | AZ12: 24/04/2026 0:00:00 | BA12: 24/04/2026 9:47:51 | BB12: NODO SCZ212 | BC12: NODO SCZ212 RAMAL A TAP 005 | BD12: MAKIRO | BE12: 3744 | BF12: DANIEL CARREÑO ROJAS | BG12: MAKIRO | BH12: 25/05/2026 16:02:39 | BI12: 16329 | BJ12: =CONS -> #NAME? | BK12: =VLOOKUP(Hoja1!$B12,Tabla2[[#All],[ID_TRANSACCION]],1,FALSE) -> #N/A
A13: 24/04/2026 0:00:00 | B13: BO_FS_202604242652480_28970435 | C13: 28970435 | D13: NULL | E13: 24/04/2026 0:00:00 | F13: NULL | G13: NULL | H13: AMELIA TEREZA FLORES ACEVEDO | I13: 2652480 | J13: NULL | K13: amelia@gmail.com | L13: Instalacion | M13: 24/04/2026 0:00:00 | N13: Instalacion / Activacion | O13: Si | P13: NULL | Q13: 10 | R13: Muy puntual y asistencia rápida | S13: NULL | T13: NULL | U13: NULL | V13: SI | W13: Yes | X13: HFC | Y13: NULL | Z13: PROMOTOR | AA13: NULL | AB13: NULL | AC13: NULL | AD13: NULL | AE13: NULL | AF13: NULL | AG13: NULL | AH13: SANTA CRUZ | AI13: SANTA CRUZ CAP | AJ13: JOSE JONATHAN VERA GUTIERREZ | AK13: 2652480 | AL13: 28970435 | AM13: AMELIA TEREZA FLORES ACEVEDO | AN13: CONECTADO | AO13: SANTA CRUZ | AP13: EAST | AQ13: SANTA CRUZ CAP | AR13: URBANA | AS13: HFC | AT13: I | AU13: FINALIZADA | AV13: 23/04/2026 0:00:00 | AW13: 23/04/2026 16:34:07 | AX13: 202604 | AY13: 24 | AZ13: 24/04/2026 0:00:00 | BA13: 24/04/2026 9:22:12 | BB13: NODO SCZ272 | BC13: NODO SCZ272 RAMAL B TAP 026 | BD13: MAKIRO | BE13: 3744 | BF13: DANIEL CARREÑO ROJAS | BG13: MAKIRO | BH13: 25/05/2026 16:02:39 | BI13: 16330 | BJ13: =CONS -> #NAME? | BK13: =VLOOKUP(Hoja1!$B13,Tabla2[[#All],[ID_TRANSACCION]],1,FALSE) -> #N/A
A14: 23/04/2026 0:00:00 | B14: BO_FS_202604232651124_28898303 | C14: 28898303 | D14: NULL | E14: 24/04/2026 0:00:00 | F14: NULL | G14: NULL | H14: Cristina SANCHEZ VACA | I14: 2651124 | J14: NULL | K14: montenegrogriselda449@gmail.com | L14: Instalacion | M14: 23/04/2026 0:00:00 | N14: Instalacion / Activacion | O14: No | P14: NULL | Q14: 9 | R14: NULL | S14: NULL | T14: NULL | U14: NULL | V14: SI | W14: Yes | X14: HFC | Y14: NULL | Z14: PROMOTOR | AA14: NULL | AB14: NULL | AC14: NULL | AD14: NULL | AE14: NULL | AF14: NULL | AG14: NULL | AH14: SANTA CRUZ | AI14: SANTA CRUZ CAP | AJ14: JOSE JONATHAN VERA GUTIERREZ | AK14: 2651124 | AL14: 28898303 | AM14: Cristina SANCHEZ VACA | AN14: CONECTADO | AO14: SANTA CRUZ | AP14: EAST | AQ14: SANTA CRUZ CAP | AR14: URBANA | AS14: HFC | AT14: I | AU14: FINALIZADA | AV14: 23/04/2026 0:00:00 | AW14: 23/04/2026 12:03:09 | AX14: 202604 | AY14: 23 | AZ14: 23/04/2026 0:00:00 | BA14: 23/04/2026 18:55:48 | BB14: NODO SCZ289 | BC14: NODO SCZ289 RAMAL B TAP 008 | BD14: MAKIRO | BE14: 3744 | BF14: DANIEL CARREÑO ROJAS | BG14: MAKIRO | BH14: 25/05/2026 16:02:39 | BI14: 16331 | BJ14: =CONS -> #NAME? | BK14: =VLOOKUP(Hoja1!$B14,Tabla2[[#All],[ID_TRANSACCION]],1,FALSE) -> #N/A
A15: 24/04/2026 0:00:00 | B15: BO_FS_202604242652447_28970246 | C15: 28970246 | D15: NULL | E15: 24/04/2026 0:00:00 | F15: NULL | G15: NULL | H15: Camila QUIROZ CESPEDES | I15: 2652447 | J15: NULL | K15: camilaquiroz05@gmail.com | L15: Instalacion | M15: 24/04/2026 0:00:00 | N15: Instalacion / Activacion | O15: No | P15: NULL | Q15: 10 | R15: Buena atención y muy amables | S15: NULL | T15: NULL | U15: NULL | V15: SI | W15: Yes | X15: HFC | Y15: NULL | Z15: PROMOTOR | AA15: NULL | AB15: NULL | AC15: NULL | AD15: NULL | AE15: NULL | AF15: NULL | AG15: NULL | AH15: SANTA CRUZ | AI15: SANTA CRUZ CAP | AJ15: JOSE JONATHAN VERA GUTIERREZ | AK15: 2652447 | AL15: 28970246 | AM15: Camila QUIROZ CESPEDES | AN15: CONECTADO | AO15: SANTA CRUZ | AP15: EAST | AQ15: SANTA CRUZ CAP | AR15: URBANA | AS15: HFC | AT15: I | AU15: FINALIZADA | AV15: 23/04/2026 0:00:00 | AW15: 23/04/2026 16:03:19 | AX15: 202604 | AY15: 24 | AZ15: 24/04/2026 0:00:00 | BA15: 24/04/2026 9:53:29 | BB15: NODO SCZ219 | BC15: NODO SCZ219 RAMAL D TAP 015 | BD15: MAKIRO | BE15: 3744 | BF15: DANIEL CARREÑO ROJAS | BG15: MAKIRO | BH15: 25/05/2026 16:02:39 | BI15: 16344 | BJ15: =CONS -> #NAME? | BK15: =VLOOKUP(Hoja1!$B15,Tabla2[[#All],[ID_TRANSACCION]],1,FALSE) -> #N/A
A16: 28/04/2026 0:00:00 | B16: BO_FS_202604282654307_29096254 | C16: 29096254 | D16: NULL | E16: 28/04/2026 0:00:00 | F16: NULL | G16: NULL | H16: GUILLMABY MATUTANO | I16: 2654307 | J16: NULL | K16: sincorreo@gmail.com | L16: Instalacion | M16: 28/04/2026 0:00:00 | N16: Instalacion / Activacion | O16: No | P16: NULL | Q16: 10 | R16: Fueron muy amables | S16: NULL | T16: NULL | U16: NULL | V16: SI | W16: NULL | X16: HFC | Y16: NULL | Z16: PROMOTOR | AA16: NULL | AB16: NULL | AC16: NULL | AD16: NULL | AE16: NULL | AF16: NULL | AG16: NULL | AH16: SANTA CRUZ | AI16: SANTA CRUZ CAP | AJ16: JOSE JONATHAN VERA GUTIERREZ | AK16: 2654307 | AL16: 29096254 | AM16: GUILLMABY MATUTANO | AN16: CONECTADO | AO16: SANTA CRUZ | AP16: EAST | AQ16: SANTA CRUZ CAP | AR16: URBANA | AS16: HFC | AT16: I | AU16: FINALIZADA | AV16: 28/04/2026 0:00:00 | AW16: 28/04/2026 10:03:18 | AX16: 202604 | AY16: 28 | AZ16: 28/04/2026 0:00:00 | BA16: 28/04/2026 15:07:54 | BB16: NODO SCZ284 | BC16: NODO SCZ284 RAMAL C TAP 010 | BD16: MAKIRO | BE16: 3744 | BF16: DANIEL CARREÑO ROJAS | BG16: MAKIRO | BH16: 25/05/2026 16:02:39 | BI16: 16345 | BJ16: =CONS -> #NAME? | BK16: =VLOOKUP(Hoja1!$B16,Tabla2[[#All],[ID_TRANSACCION]],1,FALSE) -> #N/A
A17: 27/04/2026 0:00:00 | B17: BO_FS_202604272652914_29028168 | C17: 29028168 | D17: NULL | E17: 28/04/2026 0:00:00 | F17: NULL | G17: NULL | H17: Cinthia JANCO MAMANI | I17: 2652914 | J17: NULL | K17: jancomamanic@gmail.com | L17: Instalacion | M17: 27/04/2026 0:00:00 | N17: Instalacion / Activacion | O17: No | P17: NULL | Q17: 9 | R17: NULL | S17: NULL | T17: NULL | U17: NULL | V17: SI | W17: Yes | X17: HFC | Y17: NULL | Z17: PROMOTOR | AA17: NULL | AB17: NULL | AC17: NULL | AD17: NULL | AE17: NULL | AF17: NULL | AG17: NULL | AH17: SANTA CRUZ | AI17: SANTA CRUZ CAP | AJ17: JOSE JONATHAN VERA GUTIERREZ | AK17: 2652914 | AL17: 29028168 | AM17: Cinthia JANCO MAMANI | AN17: CONECTADO | AO17: SANTA CRUZ | AP17: EAST | AQ17: SANTA CRUZ CAP | AR17: URBANA | AS17: HFC | AT17: I | AU17: FINALIZADA | AV17: 27/04/2026 0:00:00 | AW17: 27/04/2026 8:37:01 | AX17: 202604 | AY17: 27 | AZ17: 27/04/2026 0:00:00 | BA17: 27/04/2026 12:28:48 | BB17: NODO SCZ286 | BC17: NODO SCZ286 RAMAL B TAP 014 | BD17: MAKIRO | BE17: 3744 | BF17: DANIEL CARREÑO ROJAS | BG17: MAKIRO | BH17: 25/05/2026 16:02:39 | BI17: 16352 | BJ17: =CONS -> #NAME? | BK17: =VLOOKUP(Hoja1!$B17,Tabla2[[#All],[ID_TRANSACCION]],1,FALSE) -> #N/A
A18: 23/04/2026 0:00:00 | B18: BO_FS_202604232650508_28894505 | C18: 28894505 | D18: NULL | E18: 24/04/2026 0:00:00 | F18: NULL | G18: NULL | H18: Delia SALAZAR ALIENDRES | I18: 2650508 | J18: NULL | K18: Delialiendre123@gmaill.com | L18: Instalacion | M18: 23/04/2026 0:00:00 | N18: Instalacion / Activacion | O18: No | P18: NULL | Q18: 10 | R18: NULL | S18: NULL | T18: NULL | U18: NULL | V18: SI | W18: Yes | X18: HFC | Y18: NULL | Z18: PROMOTOR | AA18: NULL | AB18: NULL | AC18: NULL | AD18: NULL | AE18: NULL | AF18: NULL | AG18: NULL | AH18: SANTA CRUZ | AI18: SANTA CRUZ CAP | AJ18: JOSE JONATHAN VERA GUTIERREZ | AK18: 2650508 | AL18: 28894505 | AM18: Delia SALAZAR ALIENDRES | AN18: CONECTADO | AO18: SANTA CRUZ | AP18: EAST | AQ18: SANTA CRUZ CAP | AR18: URBANA | AS18: HFC | AT18: I | AU18: FINALIZADA | AV18: 23/04/2026 0:00:00 | AW18: 23/04/2026 12:01:53 | AX18: 202604 | AY18: 23 | AZ18: 23/04/2026 0:00:00 | BA18: 23/04/2026 18:50:24 | BB18: NODO SCZ927 | BC18: NODO SCZ927 RAMAL D TAP 023 | BD18: MAKIRO | BE18: 3744 | BF18: DANIEL CARREÑO ROJAS | BG18: MAKIRO | BH18: 25/05/2026 16:02:39 | BI18: 16381 | BJ18: =CONS -> #NAME? | BK18: =VLOOKUP(Hoja1!$B18,Tabla2[[#All],[ID_TRANSACCION]],1,FALSE) -> #N/A
A19: 27/04/2026 0:00:00 | B19: BO_FS_202604272653238_29087653 | C19: 29087653 | D19: NULL | E19: 28/04/2026 0:00:00 | F19: NULL | G19: NULL | H19: Maria cruz FARELL MORENO | I19: 2653238 | J19: NULL | K19: Florcruz35@gmail.vom | L19: Instalacion | M19: 27/04/2026 0:00:00 | N19: Instalacion / Activacion | O19: No | P19: NULL | Q19: 10 | R19: NULL | S19: NULL | T19: NULL | U19: NULL | V19: SI | W19: Yes | X19: HFC | Y19: NULL | Z19: PROMOTOR | AA19: NULL | AB19: NULL | AC19: NULL | AD19: NULL | AE19: NULL | AF19: NULL | AG19: NULL | AH19: SANTA CRUZ | AI19: SANTA CRUZ CAP | AJ19: JOSE JONATHAN VERA GUTIERREZ | AK19: 2653238 | AL19: 29087653 | AM19: María cruz FARELL MORENO | AN19: CONECTADO | AO19: SANTA CRUZ | AP19: EAST | AQ19: SANTA CRUZ CAP | AR19: URBANA | AS19: HFC | AT19: I | AU19: FINALIZADA | AV19: 25/04/2026 0:00:00 | AW19: 25/04/2026 11:15:23 | AX19: 202604 | AY19: 27 | AZ19: 27/04/2026 0:00:00 | BA19: 27/04/2026 16:46:17 | BB19: NODO SCZ461 | BC19: NODO SCZ461 RAMAL D TAP 040 | BD19: MAKIRO | BE19: 3744 | BF19: DANIEL CARREÑO ROJAS | BG19: MAKIRO | BH19: 25/05/2026 16:02:39 | BI19: 16384 | BJ19: =CONS -> #NAME? | BK19: =VLOOKUP(Hoja1!$B19,Tabla2[[#All],[ID_TRANSACCION]],1,FALSE) -> #N/A
... A21: 28/04/2026 0:00:00 | B21: BO_FS_202604282654485_29097570 | C21: 29097570 | D21: NULL | E21: 28/04/2026 0:00:00 | F21: NULL | G21: NULL | H21: CARLOS NICOLAS MACHICADO PORTELA | I21: 2654485 | J21: NULL | K21: jakerlu19@gmail.com | L21: Instalacion | M21: 28/04/2026 0:00:00 | N21: Instalacion / Activacion | O21: No | P21: NULL | Q21: 9 | R21: La instalación tuvo una respuesta rapida | S21: NULL | T21: NULL | U21: NULL | V21: SI | W21: Yes | X21: HFC | Y21: NULL | Z21: PROMOTOR | AA21: NULL | AB21: NULL | AC21: NULL | AD21: NULL | AE21: NULL | AF21: NULL | AG21: NULL | AH21: SANTA CRUZ | AI21: SANTA CRUZ CAP | AJ21: JOSE JONATHAN VERA GUTIERREZ | AK21: 2654485 | AL21: 29097570 | AM21: CARLOS NICOLAS MACHICADO PORTELA | AN21: CONECTADO | AO21: SANTA CRUZ | AP21: EAST | AQ21: SANTA CRUZ CAP | AR21: URBANA | AS21: HFC | AT21: I | AU21: FINALIZADA | AV21: 28/04/2026 0:00:00 | AW21: 28/04/2026 12:44:11 | AX21: 202604 | AY21: 28 | AZ21: 28/04/2026 0:00:00 | BA21: 28/04/2026 17:52:52 | BB21: NODO SCZ926 | BC21: NODO SCZ926 RAMAL D TAP 010 | BD21: MAKIRO | BE21: 3744 | BF21: DANIEL CARREÑO ROJAS | BG21: MAKIRO | BH21: 25/05/2026 16:02:39 | BI21: 16386 | BJ21: =CONS -> #NAME? | BK21: =VLOOKUP(Hoja1!$B21,Tabla2[[#All],[ID_TRANSACCION]],1,FALSE) -> #N/A
A22: 15/05/2026 0:00:00 | B22: BO_FS_202605152660990_29168521 | C22: 29168521 | D22: NULL | E22: 18/05/2026 0:00:00 | F22: NULL | G22: NULL | H22: FABIOLA MAMANI CHOQUE | I22: 2660990 | J22: NULL | K22: fabiolamamanich32@gmail.com | L22: Instalacion | M22: 15/05/2026 0:00:00 | N22: Instalacion / Activacion | O22: No | P22: NULL | Q22: 10 | R22: Hicieron un buen trabajo:) | S22: NULL | T22: NULL | U22: NULL | V22: SI | W22: Yes | X22: HFC | Y22: NULL | Z22: PROMOTOR | AA22: NULL | AB22: NULL | AC22: NULL | AD22: NULL | AE22: NULL | AF22: NULL | AG22: NULL | AH22: SANTA CRUZ | AI22: SANTA CRUZ CAP | AJ22: JOSE JONATHAN VERA GUTIERREZ | AK22: 2660990 | AL22: 29168521 | AM22: FABIOLA MAMANI CHOQUE | AN22: CONECTADO | AO22: SANTA CRUZ | AP22: EAST | AQ22: SANTA CRUZ CAP | AR22: URBANA | AS22: HFC | AT22: I | AU22: FINALIZADA | AV22: 14/05/2026 0:00:00 | AW22: 14/05/2026 10:17:09 | AX22: 202605 | AY22: 15 | AZ22: 15/05/2026 0:00:00 | BA22: 15/05/2026 10:12:51 | BB22: NODO SCZ321 | BC22: NODO SCZ321 RAMAL C TAP 030 | BD22: MAKIRO | BE22: 3744 | BF22: DANIEL CARREÑO ROJAS | BG22: MAKIRO | BH22: 25/05/2026 16:02:39 | BI22: 16487 | BK22: =VLOOKUP(Hoja1!$B22,Tabla2[[#All],[ID_TRANSACCION]],1,FALSE) -> BO_FS_202605152660990_29168521
A23: 15/05/2026 0:00:00 | B23: BO_FS_202605152662795_29179740 | C23: 29179740 | D23: NULL | E23: 18/05/2026 0:00:00 | F23: NULL | G23: NULL | H23: Roger RAMON PADILLA | I23: 2662795 | J23: NULL | K23: ramonpadillaroger@gmail.com | L23: Instalacion | M23: 15/05/2026 0:00:00 | N23: Instalacion / Activacion | O23: No | P23: NULL | Q23: 10 | R23: 10 | S23: NULL | T23: NULL | U23: NULL | V23: SI | W23: Yes | X23: HFC | Y23: NULL | Z23: PROMOTOR | AA23: NULL | AB23: NULL | AC23: NULL | AD23: NULL | AE23: NULL | AF23: NULL | AG23: NULL | AH23: SANTA CRUZ | AI23: SANTA CRUZ CAP | AJ23: JOSE JONATHAN VERA GUTIERREZ | AK23: 2662795 | AL23: 29179740 | AM23: Roger RAMÓN PADILLA | AN23: CONECTADO | AO23: SANTA CRUZ | AP23: EAST | AQ23: SANTA CRUZ CAP | AR23: URBANA | AS23: HFC | AT23: I | AU23: FINALIZADA | AV23: 14/05/2026 0:00:00 | AW23: 14/05/2026 13:18:52 | AX23: 202605 | AY23: 15 | AZ23: 15/05/2026 0:00:00 | BA23: 15/05/2026 13:43:36 | BB23: NODO SCZ285 | BC23: NODO SCZ285 RAMAL B TAP 039 | BD23: MAKIRO | BE23: 3744 | BF23: DANIEL CARREÑO ROJAS | BG23: MAKIRO | BH23: 25/05/2026 16:02:39 | BI23: 16489 | BK23: =VLOOKUP(Hoja1!$B23,Tabla2[[#All],[ID_TRANSACCION]],1,FALSE) -> BO_FS_202605152662795_29179740
A24: 15/05/2026 0:00:00 | B24: BO_FS_202605152662378_29176801 | C24: 29176801 | D24: NULL | E24: 18/05/2026 0:00:00 | F24: NULL | G24: NULL | H24: Erwin CHAMBI RICALDEZ | I24: 2662378 | J24: NULL | K24: Erwin12@gmail.com | L24: Instalacion | M24: 15/05/2026 0:00:00 | N24: Instalacion / Activacion | O24: No | P24: NULL | Q24: 10 | R24: NULL | S24: NULL | T24: NULL | U24: NULL | V24: SI | W24: Yes | X24: HFC | Y24: NULL | Z24: PROMOTOR | AA24: NULL | AB24: NULL | AC24: NULL | AD24: NULL | AE24: NULL | AF24: NULL | AG24: NULL | AH24: SANTA CRUZ | AI24: SANTA CRUZ CAP | AJ24: JOSE JONATHAN VERA GUTIERREZ | AK24: 2662378 | AL24: 29176801 | AM24: Erwin CHAMBI RICALDEZ | AN24: CONECTADO | AO24: SANTA CRUZ | AP24: EAST | AQ24: SANTA CRUZ CAP | AR24: URBANA | AS24: HFC | AT24: I | AU24: FINALIZADA | AV24: 13/05/2026 0:00:00 | AW24: 13/05/2026 16:46:19 | AX24: 202605 | AY24: 15 | AZ24: 15/05/2026 0:00:00 | BA24: 15/05/2026 9:57:10 | BB24: NODO SCZ267 | BC24: NODO SCZ267 RAMAL C TAP 026 | BD24: MAKIRO | BE24: 3744 | BF24: DANIEL CARREÑO ROJAS | BG24: MAKIRO | BH24: 25/05/2026 16:02:39 | BI24: 16535 | BK24: =VLOOKUP(Hoja1!$B24,Tabla2[[#All],[ID_TRANSACCION]],1,FALSE) -> BO_FS_202605152662378_29176801
A25: 14/05/2026 0:00:00 | B25: BO_FS_202605142661045_29168783 | C25: 29168783 | D25: NULL | E25: 17/05/2026 0:00:00 | F25: NULL | G25: NULL | H25: CARLOS OSWALDO DACOSTA LIJERON | I25: 2661045 | J25: NULL | K25: dacostal@gmail.com | L25: Instalacion | M25: 14/05/2026 0:00:00 | N25: Instalacion / Activacion | O25: No | P25: NULL | Q25: 10 | R25: NULL | S25: NULL | T25: NULL | U25: NULL | V25: SI | W25: Yes | X25: HFC | Y25: NULL | Z25: PROMOTOR | AA25: NULL | AB25: NULL | AC25: NULL | AD25: NULL | AE25: NULL | AF25: NULL | AG25: NULL | AH25: SANTA CRUZ | AI25: SANTA CRUZ CAP | AJ25: JOSE JONATHAN VERA GUTIERREZ | AK25: 2661045 | AL25: 29168783 | AM25: CARLOS OSWALDO DACOSTA LIJERON | AN25: CONECTADO | AO25: SANTA CRUZ | AP25: EAST | AQ25: SANTA CRUZ CAP | AR25: URBANA | AS25: HFC | AT25: I | AU25: FINALIZADA | AV25: 14/05/2026 0:00:00 | AW25: 14/05/2026 12:35:29 | AX25: 202605 | AY25: 14 | AZ25: 14/05/2026 0:00:00 | BA25: 14/05/2026 19:50:34 | BB25: NODO SCZ123 | BC25: NODO SCZ123 RAMAL C TAP 030 | BD25: MAKIRO | BE25: 3744 | BF25: DANIEL CARREÑO ROJAS | BG25: MAKIRO | BH25: 25/05/2026 16:02:39 | BI25: 16550 | BK25: =VLOOKUP(Hoja1!$B25,Tabla2[[#All],[ID_TRANSACCION]],1,FALSE) -> BO_FS_202605142661045_29168783
A26: 14/05/2026 0:00:00 | B26: BO_FS_202605142661655_29173424 | C26: 29173424 | D26: NULL | E26: 17/05/2026 0:00:00 | F26: NULL | G26: NULL | H26: Hope Noemy PONCE MENDOZA | I26: 2661655 | J26: NULL | K26: bgalarzaponce@gmail.com | L26: Instalacion | M26: 14/05/2026 0:00:00 | N26: Instalacion / Activacion | O26: No | P26: NULL | Q26: 8 | R26: NULL | S26: NULL | T26: NULL | U26: NULL | V26: SI | W26: Yes | X26: HFC | Y26: NULL | Z26: PASIVO | AA26: NULL | AB26: NULL | AC26: NULL | AD26: NULL | AE26: NULL | AF26: NULL | AG26: NULL | AH26: SANTA CRUZ | AI26: SANTA CRUZ CAP | AJ26: JOSE JONATHAN VERA GUTIERREZ | AK26: 2661655 | AL26: 29173424 | AM26: Hope Noemy PONCE MENDOZA | AN26: CONECTADO | AO26: SANTA CRUZ | AP26: EAST | AQ26: SANTA CRUZ CAP | AR26: URBANA | AS26: HFC | AT26: I | AU26: FINALIZADA | AV26: 13/05/2026 0:00:00 | AW26: 13/05/2026 9:13:50 | AX26: 202605 | AY26: 14 | AZ26: 14/05/2026 0:00:00 | BA26: 14/05/2026 12:25:02 | BB26: NODO GRD178 | BC26: NODO GRD178 RAMAL D TAP 044 | BD26: MAKIRO | BE26: 3744 | BF26: DANIEL CARREÑO ROJAS | BG26: MAKIRO | BH26: 25/05/2026 16:02:39 | BI26: 16557 | BK26: =VLOOKUP(Hoja1!$B26,Tabla2[[#All],[ID_TRANSACCION]],1,FALSE) -> BO_FS_202605142661655_29173424
A27: 21/05/2026 0:00:00 | B27: BO_FS_202605212665678_29200626 | C27: 29200626 | D27: NULL | E27: 24/05/2026 0:00:00 | F27: NULL | G27: NULL | H27: Jhon Daniel JAIMES CARVALLO | I27: 2665678 | J27: NULL | K27: jaimesdaniel082@gmail.com | L27: Instalacion | M27: 21/05/2026 0:00:00 | N27: Instalacion / Activacion | O27: No | P27: NULL | Q27: 10 | R27: Asistencia rapida | S27: NULL | T27: NULL | U27: NULL | V27: SI | W27: Yes | X27: HFC | Y27: NULL | Z27: PROMOTOR | AA27: NULL | AB27: NULL | AC27: NULL | AD27: NULL | AE27: NULL | AF27: NULL | AG27: NULL | AH27: SANTA CRUZ | AI27: SANTA CRUZ CAP | AJ27: JOSE JONATHAN VERA GUTIERREZ | AK27: 2665678 | AL27: 29200626 | AM27: Jhon Daniel JAIMES CARVALLO | AN27: CONECTADO | AO27: SANTA CRUZ | AP27: EAST | AQ27: SANTA CRUZ CAP | AR27: URBANA | AS27: HFC | AT27: I | AU27: FINALIZADA | AV27: 20/05/2026 0:00:00 | AW27: 20/05/2026 16:11:23 | AX27: 202605 | AY27: 21 | AZ27: 21/05/2026 0:00:00 | BA27: 21/05/2026 9:47:23 | BB27: NODO SCZ846 | BC27: NODO SCZ846 RAMAL B TAP 030 | BD27: MAKIRO | BE27: 3744 | BF27: DANIEL CARREÑO ROJAS | BG27: MAKIRO | BH27: 25/05/2026 16:02:39 | BI27: 16559 | BK27: =VLOOKUP(Hoja1!$B27,Tabla2[[#All],[ID_TRANSACCION]],1,FALSE) -> BO_FS_202605212665678_29200626
A28: 23/05/2026 0:00:00 | B28: BO_FS_202605232666965_29209953 | C28: 29209953 | D28: NULL | E28: 24/05/2026 0:00:00 | F28: NULL | G28: NULL | H28: ANTONIO YAVITA ROSALES | I28: 2666965 | J28: NULL | K28: guirapoiguayavitajudith@gmail.com | L28: Instalacion | M28: 23/05/2026 0:00:00 | N28: Instalacion / Activacion | O28: No | P28: NULL | Q28: 8 | R28: NULL | S28: NULL | T28: NULL | U28: NULL | V28: SI | W28: Yes | X28: HFC | Y28: NULL | Z28: PASIVO | AA28: NULL | AB28: NULL | AC28: NULL | AD28: NULL | AE28: NULL | AF28: NULL | AG28: NULL | AH28: SANTA CRUZ | AI28: SANTA CRUZ CAP | AJ28: JOSE JONATHAN VERA GUTIERREZ | AK28: 2666965 | AL28: 29209953 | AM28: ANTONIO YAVITA ROSALES | AN28: CONECTADO | AO28: SANTA CRUZ | AP28: EAST | AQ28: SANTA CRUZ CAP | AR28: URBANA | AS28: HFC | AT28: I | AU28: FINALIZADA | AV28: 23/05/2026 0:00:00 | AW28: 23/05/2026 11:17:45 | AX28: 202605 | AY28: 23 | AZ28: 23/05/2026 0:00:00 | BA28: 23/05/2026 12:38:25 | BB28: NODO SCZ271 | BC28: NODO SCZ271 RAMAL D TAP 010 | BD28: MAKIRO | BE28: 3744 | BF28: DANIEL CARREÑO ROJAS | BG28: MAKIRO | BH28: 25/05/2026 16:02:39 | BI28: 16561 | BK28: =VLOOKUP(Hoja1!$B28,Tabla2[[#All],[ID_TRANSACCION]],1,FALSE) -> BO_FS_202605232666965_29209953
A29: 23/05/2026 0:00:00 | B29: BO_FS_202605232666994_29208851 | C29: 29208851 | D29: NULL | E29: 24/05/2026 0:00:00 | F29: NULL | G29: NULL | H29: Israel ZEBALLOS TORRICO | I29: 2666994 | J29: NULL | K29: israelzeballostorrico250@gmail.com | L29: Instalacion | M29: 23/05/2026 0:00:00 | N29: Instalacion / Activacion | O29: No | P29: NULL | Q29: 10 | R29: NULL | S29: NULL | T29: NULL | U29: NULL | V29: SI | W29: Yes | X29: HFC | Y29: NULL | Z29: PROMOTOR | AA29: NULL | AB29: NULL | AC29: NULL | AD29: NULL | AE29: NULL | AF29: NULL | AG29: NULL | AH29: SANTA CRUZ | AI29: SANTA CRUZ CAP | AJ29: JOSE JONATHAN VERA GUTIERREZ | AK29: 2666994 | AL29: 29208851 | AM29: Israel ZEBALLOS TORRICO | AN29: CONECTADO | AO29: SANTA CRUZ | AP29: EAST | AQ29: SANTA CRUZ CAP | AR29: URBANA | AS29: HFC | AT29: I | AU29: FINALIZADA | AV29: 22/05/2026 0:00:00 | AW29: 22/05/2026 19:31:01 | AX29: 202605 | AY29: 23 | AZ29: 23/05/2026 0:00:00 | BA29: 23/05/2026 10:47:01 | BB29: NODO SCZ287 | BC29: NODO SCZ287 RAMAL C TAP 018 | BD29: MAKIRO | BE29: 3744 | BF29: DANIEL CARREÑO ROJAS | BG29: MAKIRO | BH29: 25/05/2026 16:02:39 | BI29: 16562 | BK29: =VLOOKUP(Hoja1!$B29,Tabla2[[#All],[ID_TRANSACCION]],1,FALSE) -> BO_FS_202605232666994_29208851
A30: 23/05/2026 0:00:00 | B30: BO_FS_202605232480261_29210542 | C30: 29210542 | D30: NULL | E30: 24/05/2026 0:00:00 | F30: NULL | G30: NULL | H30: ALFREDO VACA CASTRO | I30: 2480261 | J30: NULL | K30: sincorreo@sincorreo.com | L30: Instalacion | M30: 23/05/2026 0:00:00 | N30: Instalacion / Activacion | O30: No | P30: NULL | Q30: 9 | R30: Buena presencia, buena atención | S30: NULL | T30: NULL | U30: NULL | V30: SI | W30: Yes | X30: HFC | Y30: NULL | Z30: PROMOTOR | AA30: NULL | AB30: NULL | AC30: NULL | AD30: NULL | AE30: NULL | AF30: NULL | AG30: NULL | AH30: SANTA CRUZ | AI30: SANTA CRUZ CAP | AJ30: JOSE JONATHAN VERA GUTIERREZ | AK30: 2480261 | AL30: 29210542 | AM30: ALFREDO VACA CASTRO | AN30: CONECTADO | AO30: SANTA CRUZ | AP30: EAST | AQ30: SANTA CRUZ CAP | AR30: URBANA | AS30: HFC | AT30: I | AU30: FINALIZADA | AV30: 23/05/2026 0:00:00 | AW30: 23/05/2026 13:08:47 | AX30: 202605 | AY30: 23 | AZ30: 23/05/2026 0:00:00 | BA30: 23/05/2026 15:34:17 | BB30: NODO SCZ191 | BC30: NODO SCZ191 RAMAL B TAP 052 | BD30: MAKIRO | BE30: 3744 | BF30: DANIEL CARREÑO ROJAS | BG30: MAKIRO | BH30: 25/05/2026 16:02:39 | BI30: 16565 | BK30: =VLOOKUP(Hoja1!$B30,Tabla2[[#All],[ID_TRANSACCION]],1,FALSE) -> BO_FS_202605232480261_29210542
A31: 46117 | B31: BO_FS_202605042656640_29119172 | C31: 29119172 | D31: NULL | E31: 46208 | F31: NULL | G31: NULL | H31: NELSON ROCA COPA | I31: 2656640 | J31: NULL | K31: rocacopanelson8@gmail.com | L31: Instalacion | M31: 46117 | N31: Instalacion / Activacion | O31: No | P31: NULL | Q31: 10 | R31: Exelente servicio | S31: NULL | T31: NULL | U31: NULL | V31: SI | W31: Yes | X31: HFC | Y31: NULL | Z31: PROMOTOR | AA31: NULL | AB31: NULL | AC31: NULL | AD31: NULL | AE31: NULL | AF31: NULL | AG31: NULL | AH31: SANTA CRUZ | AI31: SANTA CRUZ CAP | AJ31: JOSE JONATHAN VERA GUTIERREZ | AK31: 2656640 | AL31: 29119172 | AM31: NELSON ROCA COPA | AN31: CONECTADO | AO31: SANTA CRUZ | AP31: EAST | AQ31: SANTA CRUZ CAP | AR31: URBANA | AS31: HFC | AT31: I | AU31: FINALIZADA | AV31: 46117 | AW31: 46117.481 | AX31: 202605 | AY31: 4 | AZ31: 46117 | BA31: 46117.538 | BB31: NODO SCZ270 | BC31: NODO SCZ270 RAMAL C TAP 023 | BD31: MAKIRO | BE31: 3744 | BF31: DANIEL CARREÑO ROJAS | BG31: MAKIRO | BH31: 25/05/2026 16:02:39 | BI31: 16602 | BJ31: =CONS -> #NAME? | BK31: =VLOOKUP(Hoja1!$B31,Tabla2[[#All],[ID_TRANSACCION]],1,FALSE) -> BO_FS_202605042656640_29119172
A32: 16/05/2026 0:00:00 | B32: BO_FS_202605162663801_29186660 | C32: 29186660 | D32: NULL | E32: 17/05/2026 0:00:00 | F32: NULL | G32: NULL | H32: Heidy AGUILAR ESPINOZA | I32: 2663801 | J32: NULL | K32: heidyaguilarewpinoza@gmail.com | L32: Instalacion | M32: 16/05/2026 0:00:00 | N32: Instalacion / Activacion | O32: No | P32: NULL | Q32: 10 | R32: NULL | S32: NULL | T32: NULL | U32: NULL | V32: SI | W32: Yes | X32: HFC | Y32: NULL | Z32: PROMOTOR | AA32: NULL | AB32: NULL | AC32: NULL | AD32: NULL | AE32: NULL | AF32: NULL | AG32: NULL | AH32: SANTA CRUZ | AI32: SANTA CRUZ CAP | AJ32: JOSE JONATHAN VERA GUTIERREZ | AK32: 2663801 | AL32: 29186660 | AM32: Heidy AGUILAR ESPINOZA | AN32: CONECTADO | AO32: SANTA CRUZ | AP32: EAST | AQ32: SANTA CRUZ CAP | AR32: URBANA | AS32: HFC | AT32: I | AU32: FINALIZADA | AV32: 16/05/2026 0:00:00 | AW32: 16/05/2026 10:38:32 | AX32: 202605 | AY32: 16 | AZ32: 16/05/2026 0:00:00 | BA32: 16/05/2026 14:42:55 | BB32: NODO SCZ209 | BC32: NODO SCZ209 RAMAL A TAP 031 | BD32: MAKIRO | BE32: 3744 | BF32: DANIEL CARREÑO ROJAS | BG32: MAKIRO | BH32: 25/05/2026 16:02:39 | BI32: 16603 | BK32: =VLOOKUP(Hoja1!$B32,Tabla2[[#All],[ID_TRANSACCION]],1,FALSE) -> BO_FS_202605162663801_29186660
A33: 17/05/2026 0:00:00 | B33: BO_FS_202605172663715_29185528 | C33: 29185528 | D33: NULL | E33: 17/05/2026 0:00:00 | F33: NULL | G33: NULL | H33: ALDRIN JUSTINIANO MONTERO | I33: 2663715 | J33: NULL | K33: aldrinjustiniano@gmail.com | L33: Instalacion | M33: 17/05/2026 0:00:00 | N33: Instalacion / Activacion | O33: No | P33: NULL | Q33: 10 | R33: Por qué es un buen servicio | S33: NULL | T33: NULL | U33: NULL | V33: SI | W33: Yes | X33: HFC | Y33: NULL | Z33: PROMOTOR | AA33: NULL | AB33: NULL | AC33: NULL | AD33: NULL | AE33: NULL | AF33: NULL | AG33: NULL | AH33: SANTA CRUZ | AI33: SANTA CRUZ CAP | AJ33: JOSE JONATHAN VERA GUTIERREZ | AK33: 2663715 | AL33: 29185528 | AM33: ALDRIN JUSTINIANO MONTERO | AN33: CONECTADO | AO33: SANTA CRUZ | AP33: EAST | AQ33: SANTA CRUZ CAP | AR33: URBANA | AS33: HFC | AT33: I | AU33: FINALIZADA | AV33: 15/05/2026 0:00:00 | AW33: 15/05/2026 20:45:21 | AX33: 202605 | AY33: 17 | AZ33: 17/05/2026 0:00:00 | BA33: 17/05/2026 9:30:18 | BB33: NODO GRD181 | BC33: NODO GRD181 RAMAL D TAP 031 | BD33: MAKIRO | BE33: 3744 | BF33: DANIEL CARREÑO ROJAS | BG33: MAKIRO | BH33: 25/05/2026 16:02:39 | BI33: 16608 | BK33: =VLOOKUP(Hoja1!$B33,Tabla2[[#All],[ID_TRANSACCION]],1,FALSE) -> BO_FS_202605172663715_29185528
A34: 14/05/2026 0:00:00 | B34: BO_FS_202605142662574_29178234 | C34: 29178234 | D34: NULL | E34: 17/05/2026 0:00:00 | F34: NULL | G34: NULL | H34: Fabiana ROJAS ARISPE | I34: 2662574 | J34: NULL | K34: fabianaroja2003@gmail.com | L34: Instalacion | M34: 14/05/2026 0:00:00 | N34: Instalacion / Activacion | O34: No | P34: NULL | Q34: 10 | R34: NULL | S34: NULL | T34: NULL | U34: NULL | V34: SI | W34: Yes | X34: HFC | Y34: NULL | Z34: PROMOTOR | AA34: NULL | AB34: NULL | AC34: NULL | AD34: NULL | AE34: NULL | AF34: NULL | AG34: NULL | AH34: SANTA CRUZ | AI34: SANTA CRUZ CAP | AJ34: JOSE JONATHAN VERA GUTIERREZ | AK34: 2662574 | AL34: 29178234 | AM34: Fabiana ROJAS ARISPE | AN34: CONECTADO | AO34: SANTA CRUZ | AP34: EAST | AQ34: SANTA CRUZ CAP | AR34: URBANA | AS34: HFC | AT34: I | AU34: FINALIZADA | AV34: 14/05/2026 0:00:00 | AW34: 14/05/2026 9:08:59 | AX34: 202605 | AY34: 14 | AZ34: 14/05/2026 0:00:00 | BA34: 14/05/2026 14:20:03 | BB34: NODO GRD269 | BC34: NODO GRD269 RAMAL C TAP 007 | BD34: MAKIRO | BE34: 3744 | BF34: DANIEL CARREÑO ROJAS | BG34: MAKIRO | BH34: 25/05/2026 16:02:39 | BI34: 16609 | BK34: =VLOOKUP(Hoja1!$B34,Tabla2[[#All],[ID_TRANSACCION]],1,FALSE) -> BO_FS_202605142662574_29178234
A35: 17/05/2026 0:00:00 | B35: BO_FS_202605172664029_29188289 | C35: 29188289 | D35: NULL | E35: 17/05/2026 0:00:00 | F35: NULL | G35: NULL | H35: Matias TORRICO ORELLANA | I35: 2664029 | J35: NULL | K35: Torrioorellanamatias@gmail.com | L35: Instalacion | M35: 17/05/2026 0:00:00 | N35: Instalacion / Activacion | O35: No | P35: NULL | Q35: 10 | R35: Muy eficiente en la instalación del equipo | S35: NULL | T35: NULL | U35: NULL | V35: NO | W35: Yes | X35: HFC | Y35: NULL | Z35: PROMOTOR | AA35: NULL | AB35: NULL | AC35: NULL | AD35: NULL | AE35: NULL | AF35: NULL | AG35: NULL | AH35: SANTA CRUZ | AI35: SANTA CRUZ CAP | AJ35: JOSE JONATHAN VERA GUTIERREZ | AK35: 2664029 | AL35: 29188289 | AM35: Matias TORRICO ORELLANA | AN35: CONECTADO | AO35: SANTA CRUZ | AP35: EAST | AQ35: SANTA CRUZ CAP | AR35: URBANA | AS35: HFC | AT35: I | AU35: FINALIZADA | AV35: 16/05/2026 0:00:00 | AW35: 16/05/2026 20:21:41 | AX35: 202605 | AY35: 17 | AZ35: 17/05/2026 0:00:00 | BA35: 17/05/2026 12:59:01 | BB35: NODO GRD181 | BC35: NODO GRD181 RAMAL A TAP 015 | BD35: MAKIRO | BE35: 3744 | BF35: DANIEL CARREÑO ROJAS | BG35: MAKIRO | BH35: 25/05/2026 16:02:39 | BI35: 16610 | BK35: =VLOOKUP(Hoja1!$B35,Tabla2[[#All],[ID_TRANSACCION]],1,FALSE) -> BO_FS_202605172664029_29188289
A36: 19/05/2026 0:00:00 | B36: BO_FS_202605192661004_29179752 | C36: 29179752 | D36: NULL | E36: 20/05/2026 0:00:00 | F36: NULL | G36: NULL | H36: JHOJAN JHOSIT MARQUEZ CORREA | I36: 2661004 | J36: NULL | K36: jhojandextroyer@gmail.com | L36: Instalacion | M36: 19/05/2026 0:00:00 | N36: Instalacion / Activacion | O36: No | P36: NULL | Q36: 10 | R36: NULL | S36: NULL | T36: NULL | U36: NULL | V36: SI | W36: Yes | X36: HFC | Y36: NULL | Z36: PROMOTOR | AA36: NULL | AB36: NULL | AC36: NULL | AD36: NULL | AE36: NULL | AF36: NULL | AG36: NULL | AH36: SANTA CRUZ | AI36: SANTA CRUZ CAP | AJ36: JOSE JONATHAN VERA GUTIERREZ | AK36: 2661004 | AL36: 29179752 | AM36: JHOJAN JHOSIT MARQUEZ CORREA | AN36: CONECTADO | AO36: SANTA CRUZ | AP36: EAST | AQ36: SANTA CRUZ CAP | AR36: URBANA | AS36: HFC | AT36: I | AU36: FINALIZADA | AV36: 19/05/2026 0:00:00 | AW36: 19/05/2026 11:19:16 | AX36: 202605 | AY36: 19 | AZ36: 19/05/2026 0:00:00 | BA36: 19/05/2026 17:01:03 | BB36: NODO SCZ270 | BC36: NODO SCZ270 RAMAL C TAP 032 | BD36: MAKIRO | BE36: 3744 | BF36: DANIEL CARREÑO ROJAS | BG36: MAKIRO | BH36: 25/05/2026 16:02:39 | BI36: 16662 | BK36: =VLOOKUP(Hoja1!$B36,Tabla2[[#All],[ID_TRANSACCION]],1,FALSE) -> BO_FS_202605192661004_29179752
A37: 13/05/2026 0:00:00 | B37: BO_FS_202605132660360_29162779 | C37: 29162779 | D37: NULL | E37: 13/05/2026 0:00:00 | F37: NULL | G37: NULL | H37: GEIDY LUCIANA PERALTA SOLIZ | I37: 2660360 | J37: NULL | K37: junior123elmen@gmail.com | L37: Instalacion | M37: 13/05/2026 0:00:00 | N37: Instalacion / Activacion | O37: No | P37: NULL | Q37: 9 | R37: Buen servicio | S37: NULL | T37: NULL | U37: NULL | V37: SI | W37: Yes | X37: HFC | Y37: NULL | Z37: PROMOTOR | AA37: NULL | AB37: NULL | AC37: NULL | AD37: NULL | AE37: NULL | AF37: NULL | AG37: NULL | AH37: SANTA CRUZ | AI37: SANTA CRUZ CAP | AJ37: JOSE JONATHAN VERA GUTIERREZ | AK37: 2660360 | AL37: 29162779 | AM37: GEIDY LUCIANA PERALTA SOLIZ | AN37: CONECTADO | AO37: SANTA CRUZ | AP37: EAST | AQ37: SANTA CRUZ CAP | AR37: URBANA | AS37: HFC | AT37: I | AU37: FINALIZADA | AV37: 13/05/2026 0:00:00 | AW37: 13/05/2026 9:42:10 | AX37: 202605 | AY37: 13 | AZ37: 13/05/2026 0:00:00 | BA37: 13/05/2026 17:22:08 | BB37: NODO SCZ291 | BC37: NODO SCZ291 RAMAL D TAP 039 | BD37: MAKIRO | BE37: 3744 | BF37: DANIEL CARREÑO ROJAS | BG37: MAKIRO | BH37: 25/05/2026 16:02:39 | BI37: 16693 | BK37: =VLOOKUP(Hoja1!$B37,Tabla2[[#All],[ID_TRANSACCION]],1,FALSE) -> BO_FS_202605132660360_29162779
A38: 46361 | B38: BO_FS_202605122661514_29170502 | C38: 29170502 | D38: NULL | E38: 13/05/2026 0:00:00 | F38: NULL | G38: NULL | H38: RUBEN DARIO CUELLAR CARDENAS | I38: 2661514 | J38: NULL | K38: rubendariocuellar@gmail.com | L38: Instalacion | M38: 46361 | N38: Instalacion / Activacion | O38: No | P38: NULL | Q38: 10 | R38: NULL | S38: NULL | T38: NULL | U38: NULL | V38: SI | W38: Yes | X38: HFC | Y38: NULL | Z38: PROMOTOR | AA38: NULL | AB38: NULL | AC38: NULL | AD38: NULL | AE38: NULL | AF38: NULL | AG38: NULL | AH38: SANTA CRUZ | AI38: SANTA CRUZ CAP | AJ38: JOSE JONATHAN VERA GUTIERREZ | AK38: 2661514 | AL38: 29170502 | AM38: RUBEN DARIO CUELLAR CARDENAS | AN38: CONECTADO | AO38: SANTA CRUZ | AP38: EAST | AQ38: SANTA CRUZ CAP | AR38: URBANA | AS38: HFC | AT38: I | AU38: FINALIZADA | AV38: 46361 | AW38: 46361.578 | AX38: 202605 | AY38: 12 | AZ38: 46361 | BA38: 46361.681 | BB38: NODO SCZ337 | BC38: NODO SCZ337 RAMAL C TAP 008 | BD38: MAKIRO | BE38: 3744 | BF38: DANIEL CARREÑO ROJAS | BG38: MAKIRO | BH38: 25/05/2026 16:02:39 | BI38: 16694 | BJ38: =CONS -> #NAME? | BK38: =VLOOKUP(Hoja1!$B38,Tabla2[[#All],[ID_TRANSACCION]],1,FALSE) -> BO_FS_202605122661514_29170502
A39: 13/05/2026 0:00:00 | B39: BO_FS_202605132661220_29169248 | C39: 29169248 | D39: NULL | E39: 13/05/2026 0:00:00 | F39: NULL | G39: NULL | H39: Fructuosa HERRERA HINOJOSA | I39: 2661220 | J39: NULL | K39: fructuosaherrera@gmail.com | L39: Instalacion | M39: 13/05/2026 0:00:00 | N39: Instalacion / Activacion | O39: No | P39: NULL | Q39: 10 | R39: Buen trabajo | S39: NULL | T39: NULL | U39: NULL | V39: SI | W39: Yes | X39: HFC | Y39: NULL | Z39: PROMOTOR | AA39: NULL | AB39: NULL | AC39: NULL | AD39: NULL | AE39: NULL | AF39: NULL | AG39: NULL | AH39: SANTA CRUZ | AI39: SANTA CRUZ CAP | AJ39: JOSE JONATHAN VERA GUTIERREZ | AK39: 2661220 | AL39: 29169248 | AM39: Fructuosa HERRERA HINOJOSA | AN39: CONECTADO | AO39: SANTA CRUZ | AP39: EAST | AQ39: SANTA CRUZ CAP | AR39: URBANA | AS39: HFC | AT39: I | AU39: FINALIZADA | AV39: 46361 | AW39: 46361.46 | AX39: 202605 | AY39: 13 | AZ39: 13/05/2026 0:00:00 | BA39: 13/05/2026 9:12:36 | BB39: NODO SCZ272 | BC39: NODO SCZ272 RAMAL C TAP 019 | BD39: MAKIRO | BE39: 3744 | BF39: DANIEL CARREÑO ROJAS | BG39: MAKIRO | BH39: 25/05/2026 16:02:39 | BI39: 16695 | BK39: =VLOOKUP(Hoja1!$B39,Tabla2[[#All],[ID_TRANSACCION]],1,FALSE) -> BO_FS_202605132661220_29169248
A40: 46361 | B40: BO_FS_202605122660805_29166472 | C40: 29166472 | D40: NULL | E40: 13/05/2026 0:00:00 | F40: NULL | G40: NULL | H40: JORGE ZABALA BECERRA | I40: 2660805 | J40: NULL | K40: Shadowalfabravo@gmail.com | L40: Instalacion | M40: 46361 | N40: Instalacion / Activacion | O40: No | P40: NULL | Q40: 9 | R40: Todo excelente por los instaladores pero solo permiten el lago del cable 50 m. Por lo que eso complica la instalación a veces | S40: NULL | T40: NULL | U40: NULL | V40: SI | W40: Yes | X40: HFC | Y40: NULL | Z40: PROMOTOR | AA40: NULL | AB40: NULL | AC40: NULL | AD40: NULL | AE40: NULL | AF40: NULL | AG40: NULL | AH40: SANTA CRUZ | AI40: SANTA CRUZ CAP | AJ40: JOSE JONATHAN VERA GUTIERREZ | AK40: 2660805 | AL40: 29166472 | AM40: JORGE ZABALA BECERRA | AN40: CONECTADO | AO40: SANTA CRUZ | AP40: EAST | AQ40: SANTA CRUZ CAP | AR40: URBANA | AS40: HFC | AT40: I | AU40: FINALIZADA | AV40: 46300 | AW40: 46300.504 | AX40: 202605 | AY40: 12 | AZ40: 46361 | BA40: 46361.621 | BB40: NODO SCZ291 | BC40: NODO SCZ291 RAMAL C TAP 016 | BD40: MAKIRO | BE40: 3744 | BF40: DANIEL CARREÑO ROJAS | BG40: MAKIRO | BH40: 25/05/2026 16:02:39 | BI40: 16696 | BJ40: =CONS -> #NAME? | BK40: =VLOOKUP(Hoja1!$B40,Tabla2[[#All],[ID_TRANSACCION]],1,FALSE) -> BO_FS_202605122660805_29166472
A41: 46361 | B41: BO_FS_202605122660786_29166307 | C41: 29166307 | D41: NULL | E41: 13/05/2026 0:00:00 | F41: NULL | G41: NULL | H41: ERIK DANIEL AGUILAR GONZALES | I41: 2660786 | J41: NULL | K41: erikdanielaguilargonzales01@gmail.com | L41: Instalacion | M41: 46361 | N41: Instalacion / Activacion | O41: No | P41: NULL | Q41: 10 | R41: Fue muy amable al instalar y me ayudó a poder colectar en un buen lugar , muy buena atención | S41: NULL | T41: NULL | U41: NULL | V41: SI | W41: Yes | X41: HFC | Y41: NULL | Z41: PROMOTOR | AA41: NULL | AB41: NULL | AC41: NULL | AD41: NULL | AE41: NULL | AF41: NULL | AG41: NULL | AH41: SANTA CRUZ | AI41: SANTA CRUZ CAP | AJ41: JOSE JONATHAN VERA GUTIERREZ | AK41: 2660786 | AL41: 29166307 | AM41: ERIK DANIEL AGUILAR GONZALES | AN41: CONECTADO | AO41: SANTA CRUZ | AP41: EAST | AQ41: SANTA CRUZ CAP | AR41: URBANA | AS41: HFC | AT41: I | AU41: FINALIZADA | AV41: 46300 | AW41: 46300.442 | AX41: 202605 | AY41: 12 | AZ41: 46361 | BA41: 46361.439 | BB41: NODO SCZ275 | BC41: NODO SCZ275 RAMAL C TAP 022 | BD41: MAKIRO | BE41: 3744 | BF41: DANIEL CARREÑO ROJAS | BG41: MAKIRO | BH41: 25/05/2026 16:02:39 | BI41: 16713 | BJ41: =CONS -> #NAME? | BK41: =VLOOKUP(Hoja1!$B41,Tabla2[[#All],[ID_TRANSACCION]],1,FALSE) -> BO_FS_202605122660786_29166307
A42: 46361 | B42: BO_FS_202605122660779_29166247 | C42: 29166247 | D42: NULL | E42: 13/05/2026 0:00:00 | F42: NULL | G42: NULL | H42: MARCO ANTONIO OLIVERA RAMOS | I42: 2660779 | J42: NULL | K42: deliciaoliveraramos@gmail.com | L42: Instalacion | M42: 46361 | N42: Instalacion / Activacion | O42: No | P42: NULL | Q42: 10 | R42: NULL | S42: NULL | T42: NULL | U42: NULL | V42: SI | W42: Yes | X42: HFC | Y42: NULL | Z42: PROMOTOR | AA42: NULL | AB42: NULL | AC42: NULL | AD42: NULL | AE42: NULL | AF42: NULL | AG42: NULL | AH42: SANTA CRUZ | AI42: SANTA CRUZ CAP | AJ42: JOSE JONATHAN VERA GUTIERREZ | AK42: 2660779 | AL42: 29166247 | AM42: MARCO ANTONIO OLIVERA RAMOS | AN42: CONECTADO | AO42: SANTA CRUZ | AP42: EAST | AQ42: SANTA CRUZ CAP | AR42: URBANA | AS42: HFC | AT42: I | AU42: FINALIZADA | AV42: 46300 | AW42: 46300.408 | AX42: 202605 | AY42: 12 | AZ42: 46361 | BA42: 46361.439 | BB42: NODO SCZ290 | BC42: NODO SCZ290 RAMAL A TAP 018 | BD42: MAKIRO | BE42: 3744 | BF42: DANIEL CARREÑO ROJAS | BG42: MAKIRO | BH42: 25/05/2026 16:02:39 | BI42: 16714 | BJ42: =CONS -> #NAME? | BK42: =VLOOKUP(Hoja1!$B42,Tabla2[[#All],[ID_TRANSACCION]],1,FALSE) -> BO_FS_202605122660779_29166247
A43: 13/05/2026 0:00:00 | B43: BO_FS_202605132657172_29122286 | C43: 29122286 | D43: NULL | E43: 13/05/2026 0:00:00 | F43: NULL | G43: NULL | H43: VEIMAR MAMANI CASTRO | I43: 2657172 | J43: NULL | K43: veimarmamanicastro1999i@gmail.com | L43: Instalacion | M43: 13/05/2026 0:00:00 | N43: Instalacion / Activacion | O43: No | P43: NULL | Q43: 10 | R43: Servicio apacible. Asesores con capacidad de entender la necesidad que tenemos los clientes | S43: NULL | T43: NULL | U43: NULL | V43: SI | W43: Yes | X43: HFC | Y43: NULL | Z43: PROMOTOR | AA43: NULL | AB43: NULL | AC43: NULL | AD43: NULL | AE43: NULL | AF43: NULL | AG43: NULL | AH43: SANTA CRUZ | AI43: SANTA CRUZ CAP | AJ43: JOSE JONATHAN VERA GUTIERREZ | AK43: 2657172 | AL43: 29122286 | AM43: VEIMAR MAMANI CASTRO | AN43: CONECTADO | AO43: SANTA CRUZ | AP43: EAST | AQ43: SANTA CRUZ CAP | AR43: URBANA | AS43: HFC | AT43: I | AU43: FINALIZADA | AV43: 46300 | AW43: 46300.673 | AX43: 202605 | AY43: 13 | AZ43: 13/05/2026 0:00:00 | BA43: 13/05/2026 15:56:13 | BB43: NODO SCZ272 | BC43: NODO SCZ272 RAMAL D TAP 019 | BD43: MAKIRO | BE43: 3744 | BF43: DANIEL CARREÑO ROJAS | BG43: MAKIRO | BH43: 25/05/2026 16:02:39 | BI43: 16715 | BK43: =VLOOKUP(Hoja1!$B43,Tabla2[[#All],[ID_TRANSACCION]],1,FALSE) -> BO_FS_202605132657172_29122286
A44: 13/05/2026 0:00:00 | B44: BO_FS_202605132661737_29172091 | C44: 29172091 | D44: NULL | E44: 13/05/2026 0:00:00 | F44: NULL | G44: NULL | H44: Wendy MENDOZA CORTEZ | I44: 2661737 | J44: NULL | K44: Wendymendoa21@gmail.com | L44: Instalacion | M44: 13/05/2026 0:00:00 | N44: Instalacion / Activacion | O44: No | P44: NULL | Q44: 10 | R44: Buen servicio | S44: NULL | T44: NULL | U44: NULL | V44: SI | W44: Yes | X44: HFC | Y44: NULL | Z44: PROMOTOR | AA44: NULL | AB44: NULL | AC44: NULL | AD44: NULL | AE44: NULL | AF44: NULL | AG44: NULL | AH44: SANTA CRUZ | AI44: SANTA CRUZ CAP | AJ44: JOSE JONATHAN VERA GUTIERREZ | AK44: 2661737 | AL44: 29172091 | AM44: Wendy MENDOZA CORTEZ | AN44: CONECTADO | AO44: SANTA CRUZ | AP44: EAST | AQ44: SANTA CRUZ CAP | AR44: URBANA | AS44: HFC | AT44: I | AU44: FINALIZADA | AV44: 46361 | AW44: 46361.725 | AX44: 202605 | AY44: 13 | AZ44: 13/05/2026 0:00:00 | BA44: 13/05/2026 11:09:51 | BB44: NODO SCZ266 | BC44: NODO SCZ266 RAMAL C TAP 020 | BD44: MAKIRO | BE44: 3744 | BF44: DANIEL CARREÑO ROJAS | BG44: MAKIRO | BH44: 25/05/2026 16:02:39 | BI44: 16716 | BK44: =VLOOKUP(Hoja1!$B44,Tabla2[[#All],[ID_TRANSACCION]],1,FALSE) -> BO_FS_202605132661737_29172091
...

Sheet Hoja2
A1: FECHA_CREACION | B1: ID_TRANSACCION | C1: NRO_ORDEN | D1: SURVEYID_FOR_INTERNAL_USE | E1: FECHA_DE_RESPUESTA | F1: TIPO_DE_ALERTA | G1: TIPO_DE_ENCUESTA | H1: NOMBRE_CLIENTE | I1: ID_CLIENTE | J1: UNIT | K1: EMAIL | L1: TIPO_DE_TRANSACCION | M1: FECHA_DE_TRANSACCION_ | N1: JOURNEY | O1: FLAG_B2B | P1: FIELD_SERV_SUBTIPO_TRAN_GLOBAL | Q1: LTR | R1: LIKELIHOOD_TO_RECOMMEND_COME | S1: CES | T1: CSAT | U1: FCR_COMMENT_EXPORT | V1: FCR | W1: CUMPLIMIENTO_DE_AGENDA | X1: Tecnologia | Y1: TA_TOPICOS_LTR | Z1: NPS_TIPO | AA1: SATISFACCION_TIEMPO_ENTREGA | AB1: IMAGEN_PERSONAL | AC1: AMABILIDAD_TECNICO | AD1: CONOCIMIENTO_TECNICO | AE1: IMAGEN_PERSONAL_2 | AF1: AMABILIDAD_TECNICO_2 | AG1: CONOCIMIENTO_TECNICO_2 | AH1: DEPARTAMENTO | AI1: CIUDAD | AJ1: SUPERVISOR_1 | AK1: CLIENTENRO | AL1: ORDENNRO | AM1: CLIENTE_NOMBRE_COMPLETO | AN1: CLIENTE_ESTADO | AO1: DEPARTAMENTO_SIGA | AP1: TERRITORY | AQ1: CIUDAD_SIGA | AR1: POBLACION_CLIENTE | AS1: TECNOLOGIA_SIGA | AT1: ORDEN_TIPO_COD | AU1: ORDEN_ESTADO | AV1: ORDEN_FECHA_REGISTRO | AW1: ORDEN_HORA_REGISTRO | AX1: ORDEN_MES_FINALIZACION | AY1: DIAFIN | AZ1: ORDEN_FECHA_FINALIZACION | BA1: ORDEN_HORA_FINALIZACION | BB1: ZONA_GRUPO | BC1: ZONA_TAP | BD1: DEALER_TECNICO_NOMBRE | BE1: TECNICOID | BF1: TECNICO_NOMBRE | BG1: Column 75 | BH1: Column 76
A2: 46146 | B2: BO_FS_202605042656640_29119172 | C2: 29119172 | E2: 46149 | H2: NELSON ROCA COPA | I2: 2656640 | K2: rocacopanelson8@gmail.com | L2: Instalacion | M2: 46146 | N2: Instalacion / Activacion | O2: No | Q2: 10 | R2: Exelente servicio | V2: SI | W2: Yes | X2: HFC | Z2: PROMOTOR | AH2: SANTA CRUZ | AI2: SANTA CRUZ CAP | AJ2: JOSE JONATHAN VERA GUTIERREZ | AK2: 2656640 | AL2: 29119172 | AM2: NELSON ROCA COPA | AN2: CONECTADO | AO2: SANTA CRUZ | AP2: EAST | AQ2: SANTA CRUZ CAP | AR2: URBANA | AS2: HFC | AT2: I | AU2: FINALIZADA | AV2: 46146 | AW2: 46146.481 | AX2: 202605 | AY2: 4 | AZ2: 46146 | BA2: 46146.538 | BB2: NODO SCZ270 | BC2: NODO SCZ270 RAMAL C TAP 023 | BD2: MAKIRO | BE2: 3744 | BF2: DANIEL CARREÑO ROJAS | BH2: =VLOOKUP(Tabla2[[#This Row],[ID_TRANSACCION]],Hoja1!$B$4:$B$55,1,FALSE) -> BO_FS_202605042656640_29119172
A3: 46149 | B3: BO_FS_202605072658950_29152051 | C3: 29152051 | E3: 46150 | H3: Katalina LOPEZ EGUEZ | I3: 2658950 | K3: Lopezeguezkatalina@gmail.com | L3: Instalacion | M3: 46149 | N3: Instalacion / Activacion | O3: No | Q3: 10 | R3: Muy bien servicio | V3: SI | W3: Yes | X3: HFC | Z3: PROMOTOR | AH3: SANTA CRUZ | AI3: SANTA CRUZ CAP | AJ3: JOSE JONATHAN VERA GUTIERREZ | AK3: 2658950 | AL3: 29152051 | AM3: Katalina LÓPEZ EGUEZ | AN3: CONECTADO | AO3: SANTA CRUZ | AP3: EAST | AQ3: SANTA CRUZ CAP | AR3: URBANA | AS3: HFC | AT3: I | AU3: FINALIZADA | AV3: 46148 | AW3: 46148.661 | AX3: 202605 | AY3: 7 | AZ3: 46149 | BA3: 46149.638 | BB3: NODO SCZ321 | BC3: NODO SCZ321 RAMAL D TAP 007 | BD3: MAKIRO | BE3: 3744 | BF3: DANIEL CARREÑO ROJAS | BH3: =VLOOKUP(Tabla2[[#This Row],[ID_TRANSACCION]],Hoja1!$B$4:$B$55,1,FALSE) -> BO_FS_202605072658950_29152051
A4: 46150 | B4: BO_FS_202605082659753_29158085 | C4: 29158085 | E4: 46152 | H4: CRISTIAN CHUVE CHUVIRU | I4: 2659753 | K4: cristian.chuvechu@gmail.com | L4: Instalacion | M4: 46150 | N4: Instalacion / Activacion | O4: No | Q4: 10 | R4: Excelente trabajo | V4: SI | W4: Yes | X4: HFC | Z4: PROMOTOR | AH4: SANTA CRUZ | AI4: SANTA CRUZ CAP | AJ4: JOSE JONATHAN VERA GUTIERREZ | AK4: 2659753 | AL4: 29158085 | AM4: CRISTIAN CHUVE CHUVIRU | AN4: CONECTADO | AO4: SANTA CRUZ | AP4: EAST | AQ4: SANTA CRUZ CAP | AR4: URBANA | AS4: HFC | AT4: I | AU4: FINALIZADA | AV4: 46149 | AW4: 46149.808 | AX4: 202605 | AY4: 8 | AZ4: 46150 | BA4: 46150.641 | BB4: NODO SCZ270 | BC4: NODO SCZ270 RAMAL B TAP 025 | BD4: MAKIRO | BE4: 3744 | BF4: DANIEL CARREÑO ROJAS | BH4: =VLOOKUP(Tabla2[[#This Row],[ID_TRANSACCION]],Hoja1!$B$4:$B$55,1,FALSE) -> BO_FS_202605082659753_29158085
A5: 46154 | B5: BO_FS_202605122661514_29170502 | C5: 29170502 | E5: 46155 | H5: RUBEN DARIO CUELLAR CARDENAS | I5: 2661514 | K5: rubendariocuellar@gmail.com | L5: Instalacion | M5: 46154 | N5: Instalacion / Activacion | O5: No | Q5: 10 | V5: SI | W5: Yes | X5: HFC | Z5: PROMOTOR | AH5: SANTA CRUZ | AI5: SANTA CRUZ CAP | AJ5: JOSE JONATHAN VERA GUTIERREZ | AK5: 2661514 | AL5: 29170502 | AM5: RUBEN DARIO CUELLAR CARDENAS | AN5: CONECTADO | AO5: SANTA CRUZ | AP5: EAST | AQ5: SANTA CRUZ CAP | AR5: URBANA | AS5: HFC | AT5: I | AU5: FINALIZADA | AV5: 46154 | AW5: 46154.578 | AX5: 202605 | AY5: 12 | AZ5: 46154 | BA5: 46154.681 | BB5: NODO SCZ337 | BC5: NODO SCZ337 RAMAL C TAP 008 | BD5: MAKIRO | BE5: 3744 | BF5: DANIEL CARREÑO ROJAS | BH5: =VLOOKUP(Tabla2[[#This Row],[ID_TRANSACCION]],Hoja1!$B$4:$B$55,1,FALSE) -> BO_FS_202605122661514_29170502
A6: 46155 | B6: BO_FS_202605132660360_29162779 | C6: 29162779 | E6: 46155 | H6: GEIDY LUCIANA PERALTA SOLIZ | I6: 2660360 | K6: junior123elmen@gmail.com | L6: Instalacion | M6: 46155 | N6: Instalacion / Activacion | O6: No | Q6: 9 | R6: Buen servicio | V6: SI | W6: Yes | X6: HFC | Z6: PROMOTOR | AH6: SANTA CRUZ | AI6: SANTA CRUZ CAP | AJ6: JOSE JONATHAN VERA GUTIERREZ | AK6: 2660360 | AL6: 29162779 | AM6: GEIDY LUCIANA PERALTA SOLIZ | AN6: CONECTADO | AO6: SANTA CRUZ | AP6: EAST | AQ6: SANTA CRUZ CAP | AR6: URBANA | AS6: HFC | AT6: I | AU6: FINALIZADA | AV6: 46155 | AW6: 46155.404 | AX6: 202605 | AY6: 13 | AZ6: 46155 | BA6: 46155.724 | BB6: NODO SCZ291 | BC6: NODO SCZ291 RAMAL D TAP 039 | BD6: MAKIRO | BE6: 3744 | BF6: DANIEL CARREÑO ROJAS | BH6: =VLOOKUP(Tabla2[[#This Row],[ID_TRANSACCION]],Hoja1!$B$4:$B$55,1,FALSE) -> BO_FS_202605132660360_29162779
A7: 46155 | B7: BO_FS_202605132661220_29169248 | C7: 29169248 | E7: 46155 | H7: Fructuosa HERRERA HINOJOSA | I7: 2661220 | K7: fructuosaherrera@gmail.com | L7: Instalacion | M7: 46155 | N7: Instalacion / Activacion | O7: No | Q7: 10 | R7: Buen trabajo | V7: SI | W7: Yes | X7: HFC | Z7: PROMOTOR | AH7: SANTA CRUZ | AI7: SANTA CRUZ CAP | AJ7: JOSE JONATHAN VERA GUTIERREZ | AK7: 2661220 | AL7: 29169248 | AM7: Fructuosa HERRERA HINOJOSA | AN7: CONECTADO | AO7: SANTA CRUZ | AP7: EAST | AQ7: SANTA CRUZ CAP | AR7: URBANA | AS7: HFC | AT7: I | AU7: FINALIZADA | AV7: 46154 | AW7: 46154.46 | AX7: 202605 | AY7: 13 | AZ7: 46155 | BA7: 46155.384 | BB7: NODO SCZ272 | BC7: NODO SCZ272 RAMAL C TAP 019 | BD7: MAKIRO | BE7: 3744 | BF7: DANIEL CARREÑO ROJAS | BH7: =VLOOKUP(Tabla2[[#This Row],[ID_TRANSACCION]],Hoja1!$B$4:$B$55,1,FALSE) -> BO_FS_202605132661220_29169248
A8: 46154 | B8: BO_FS_202605122660805_29166472 | C8: 29166472 | E8: 46155 | H8: JORGE ZABALA BECERRA | I8: 2660805 | K8: Shadowalfabravo@gmail.com | L8: Instalacion | M8: 46154 | N8: Instalacion / Activacion | O8: No | Q8: 9 | R8: Todo excelente por los instaladores pero solo permiten el lago del cable 50 m. Por lo que eso complica la instalación a veces | V8: SI | W8: Yes | X8: HFC | Z8: PROMOTOR | AH8: SANTA CRUZ | AI8: SANTA CRUZ CAP | AJ8: JOSE JONATHAN VERA GUTIERREZ | AK8: 2660805 | AL8: 29166472 | AM8: JORGE ZABALA BECERRA | AN8: CONECTADO | AO8: SANTA CRUZ | AP8: EAST | AQ8: SANTA CRUZ CAP | AR8: URBANA | AS8: HFC | AT8: I | AU8: FINALIZADA | AV8: 46152 | AW8: 46152.504 | AX8: 202605 | AY8: 12 | AZ8: 46154 | BA8: 46154.621 | BB8: NODO SCZ291 | BC8: NODO SCZ291 RAMAL C TAP 016 | BD8: MAKIRO | BE8: 3744 | BF8: DANIEL CARREÑO ROJAS | BH8: =VLOOKUP(Tabla2[[#This Row],[ID_TRANSACCION]],Hoja1!$B$4:$B$55,1,FALSE) -> BO_FS_202605122660805_29166472
A9: 46155 | B9: BO_FS_202605132657172_29122286 | C9: 29122286 | E9: 46155 | H9: VEIMAR MAMANI CASTRO | I9: 2657172 | K9: veimarmamanicastro1999i@gmail.com | L9: Instalacion | M9: 46155 | N9: Instalacion / Activacion | O9: No | Q9: 10 | R9: Servicio apacible. Asesores con capacidad de entender la necesidad que tenemos los clientes | V9: SI | W9: Yes | X9: HFC | Z9: PROMOTOR | AH9: SANTA CRUZ | AI9: SANTA CRUZ CAP | AJ9: JOSE JONATHAN VERA GUTIERREZ | AK9: 2657172 | AL9: 29122286 | AM9: VEIMAR MAMANI CASTRO | AN9: CONECTADO | AO9: SANTA CRUZ | AP9: EAST | AQ9: SANTA CRUZ CAP | AR9: URBANA | AS9: HFC | AT9: I | AU9: FINALIZADA | AV9: 46152 | AW9: 46152.673 | AX9: 202605 | AY9: 13 | AZ9: 46155 | BA9: 46155.664 | BB9: NODO SCZ272 | BC9: NODO SCZ272 RAMAL D TAP 019 | BD9: MAKIRO | BE9: 3744 | BF9: DANIEL CARREÑO ROJAS | BH9: =VLOOKUP(Tabla2[[#This Row],[ID_TRANSACCION]],Hoja1!$B$4:$B$55,1,FALSE) -> BO_FS_202605132657172_29122286
A10: 46155 | B10: BO_FS_202605132661737_29172091 | C10: 29172091 | E10: 46155 | H10: Wendy MENDOZA CORTEZ | I10: 2661737 | K10: Wendymendoa21@gmail.com | L10: Instalacion | M10: 46155 | N10: Instalacion / Activacion | O10: No | Q10: 10 | R10: Buen servicio | V10: SI | W10: Yes | X10: HFC | Z10: PROMOTOR | AH10: SANTA CRUZ | AI10: SANTA CRUZ CAP | AJ10: JOSE JONATHAN VERA GUTIERREZ | AK10: 2661737 | AL10: 29172091 | AM10: Wendy MENDOZA CORTEZ | AN10: CONECTADO | AO10: SANTA CRUZ | AP10: EAST | AQ10: SANTA CRUZ CAP | AR10: URBANA | AS10: HFC | AT10: I | AU10: FINALIZADA | AV10: 46154 | AW10: 46154.725 | AX10: 202605 | AY10: 13 | AZ10: 46155 | BA10: 46155.465 | BB10: NODO SCZ266 | BC10: NODO SCZ266 RAMAL C TAP 020 | BD10: MAKIRO | BE10: 3744 | BF10: DANIEL CARREÑO ROJAS | BH10: =VLOOKUP(Tabla2[[#This Row],[ID_TRANSACCION]],Hoja1!$B$4:$B$55,1,FALSE) -> BO_FS_202605132661737_29172091
A11: 46154 | B11: BO_FS_202605122660786_29166307 | C11: 29166307 | E11: 46155 | H11: ERIK DANIEL AGUILAR GONZALES | I11: 2660786 | K11: erikdanielaguilargonzales01@gmail.com | L11: Instalacion | M11: 46154 | N11: Instalacion / Activacion | O11: No | Q11: 10 | R11: Fue muy amable al instalar y me ayudó a poder colectar en un buen lugar , muy buena atención | V11: SI | W11: Yes | X11: HFC | Z11: PROMOTOR | AH11: SANTA CRUZ | AI11: SANTA CRUZ CAP | AJ11: JOSE JONATHAN VERA GUTIERREZ | AK11: 2660786 | AL11: 29166307 | AM11: ERIK DANIEL AGUILAR GONZALES | AN11: CONECTADO | AO11: SANTA CRUZ | AP11: EAST | AQ11: SANTA CRUZ CAP | AR11: URBANA | AS11: HFC | AT11: I | AU11: FINALIZADA | AV11: 46152 | AW11: 46152.442 | AX11: 202605 | AY11: 12 | AZ11: 46154 | BA11: 46154.439 | BB11: NODO SCZ275 | BC11: NODO SCZ275 RAMAL C TAP 022 | BD11: MAKIRO | BE11: 3744 | BF11: DANIEL CARREÑO ROJAS | BH11: =VLOOKUP(Tabla2[[#This Row],[ID_TRANSACCION]],Hoja1!$B$4:$B$55,1,FALSE) -> BO_FS_202605122660786_29166307
A12: 46154 | B12: BO_FS_202605122660779_29166247 | C12: 29166247 | E12: 46155 | H12: MARCO ANTONIO OLIVERA RAMOS | I12: 2660779 | K12: deliciaoliveraramos@gmail.com | L12: Instalacion | M12: 46154 | N12: Instalacion / Activacion | O12: No | Q12: 10 | V12: SI | W12: Yes | X12: HFC | Z12: PROMOTOR | AH12: SANTA CRUZ | AI12: SANTA CRUZ CAP | AJ12: JOSE JONATHAN VERA GUTIERREZ | AK12: 2660779 | AL12: 29166247 | AM12: MARCO ANTONIO OLIVERA RAMOS | AN12: CONECTADO | AO12: SANTA CRUZ | AP12: EAST | AQ12: SANTA CRUZ CAP | AR12: URBANA | AS12: HFC | AT12: I | AU12: FINALIZADA | AV12: 46152 | AW12: 46152.408 | AX12: 202605 | AY12: 12 | AZ12: 46154 | BA12: 46154.439 | BB12: NODO SCZ290 | BC12: NODO SCZ290 RAMAL A TAP 018 | BD12: MAKIRO | BE12: 3744 | BF12: DANIEL CARREÑO ROJAS | BH12: =VLOOKUP(Tabla2[[#This Row],[ID_TRANSACCION]],Hoja1!$B$4:$B$55,1,FALSE) -> BO_FS_202605122660779_29166247
